Workbook
Name AsOfDate: 'FX & Assumptions'!$C$5
Name FXRate: 'FX & Assumptions'!$C$6

Sheet README
B2: TH INVESTMENT — PRIVATE BANKING SUMMARY
B4: Weekly Update Workflow
B6: 1. Open "FX & Assumptions" — update the As-of Date and USDTHB spot rate (yellow cells).
B7: 2. Open "Prices" — update the yellow "Current Price / NAV" column for every MF, Equity, and Crypto row.
B8: 3. All holdings, rollups, and the Dashboard refresh automatically once prices are entered.
B9: 4. Open "Weekly Snapshot" — copy the "Current Week" row (values only) into the next empty row to log week-over-week history.
B10: 5. To reclassify holdings (asset class / geography / theme / tax status), edit the "Reference" sheet.
B11: 6. Color coding: Yellow fill + blue text = user input | Black text = formula | Green text = cross-sheet link.
B12: 7. Never overwrite black or green text — those are live formulas.
B14: Sheet Map
B16: • Dashboard — One-page executive summary — total NAV, total P&L, asset-class / geography / tax-status allocation, top 10 holdings, breakdown tables.
B17: • Weekly Snapshot — History log of total portfolio value and P&L per week; append one row per week.
... B33: • Rollups are SUMIFS-driven, so adding a new lot at the bottom of a Lots sheet (within the pre-built range) is automatically picked up.

Sheet Dashboard
B2: PORTFOLIO DASHBOARD
B3: As of: | C3: =AsOfDate
B5: SUMMARY METRICS
B7: TOTAL PORTFOLIO VALUE (THB) | F7: TOTAL INVESTED (THB) | J7: UNREALIZED P&L (THB)
B8: ='MF - Lots'!P165+'Equities - Lots'!M46+'Crypto - Lots'!K31 | F8: ='MF - Lots'!O165+'Equities - Lots'!L46+'Crypto - Lots'!J31 | J8: ='MF - Lots'!Q165+'Equities - Lots'!N46+'Crypto - Lots'!L31
B10: P&L % (CUMULATIVE) | F10: MF | EQUITIES | CRYPTO | J10: USD / THB USED
B11: =IFERROR(('MF - Lots'!Q165+'Equities - Lots'!N46+'Crypto - Lots'!L31)/('MF - Lots'!O165+'Equities - Lots'!L46+'Crypto - Lots'!J31),0) | F11: =COUNTA('MF - Lots'!C5:C164)&" / "&COUNTA('Equities - Lots'!C5:C45)&" / "&COUNTA('Crypto - Lots'!C5:C30) | J11: =FXRate
B14: ASSET CLASS ALLOCATION (THB) | H14: GEOGRAPHY ALLOCATION (THB)
B15: Asset Class | C15: Invested | D15: Current Value | E15: % of Port | F15: P&L | H15: Geography | I15: Invested | J15: Current Value | K15: % of Port | L15: P&L
B16: Equity | C16: =SUMIFS('MF - Lots'!$O:$O,'MF - Lots'!$D:$D,B16)+SUMIFS('Equities - Lots'!$L:$L,'Equities - Lots'!$E:$E,B16)+IF(B16="Digital Assets",'Crypto - Lots'!J31,0) | D16: =SUMIFS('MF - Lots'!$P:$P,'MF - Lots'!$D:$D,B16)+SUMIFS('Equities - Lots'!$M:$M,'Equities - Lots'!$E:$E,B16)+IF(B16="Digital Assets",'Crypto - Lots'!K31,0) | E16: =IFERROR(D16/SUM($D$16:$D$21),0) | F16: =D16-C16 | H16: Thailand | I16: =SUMIFS('MF - Lots'!$O:$O,'MF - Lots'!$F:$F,H16)+SUMIFS('Equities - Lots'!$L:$L,'Equities - Lots'!$F:$F,H16)+IF(H16="Global",'Crypto - Lots'!J31,0) | J16: =SUMIFS('MF - Lots'!$P:$P,'MF - Lots'!$F:$F,H16)+SUMIFS('Equities - Lots'!$M:$M,'Equities - Lots'!$F:$F,H16)+IF(H16="Global",'Crypto - Lots'!K31,0) | K16: =IFERROR(J16/SUM($J$16:$J$23),0) | L16: =J16-I16
B17: Fixed Income | C17: =SUMIFS('MF - Lots'!$O:$O,'MF - Lots'!$D:$D,B17)+SUMIFS('Equities - Lots'!$L:$L,'Equities - Lots'!$E:$E,B17)+IF(B17="Digital Assets",'Crypto - Lots'!J31,0) | D17: =SUMIFS('MF - Lots'!$P:$P,'MF - Lots'!$D:$D,B17)+SUMIFS('Equities - Lots'!$M:$M,'Equities - Lots'!$E:$E,B17)+IF(B17="Digital Assets",'Crypto - Lots'!K31,0) | E17: =IFERROR(D17/SUM($D$16:$D$21),0) | F17: =D17-C17 | H17: United States | I17: =SUMIFS('MF - Lots'!$O:$O,'MF - Lots'!$F:$F,H17)+SUMIFS('Equities - Lots'!$L:$L,'Equities - Lots'!$F:$F,H17)+IF(H17="Global",'Crypto - Lots'!J31,0) | J17: =SUMIFS('MF - Lots'!$P:$P,'MF - Lots'!$F:$F,H17)+SUMIFS('Equities - Lots'!$M:$M,'Equities - Lots'!$F:$F,H17)+IF(H17="Global",'Crypto - Lots'!K31,0) | K17: =IFERROR(J17/SUM($J$16:$J$23),0) | L17: =J17-I17
B18: Multi-Asset | C18: =SUMIFS('MF - Lots'!$O:$O,'MF - Lots'!$D:$D,B18)+SUMIFS('Equities - Lots'!$L:$L,'Equities - Lots'!$E:$E,B18)+IF(B18="Digital Assets",'Crypto - Lots'!J31,0) | D18: =SUMIFS('MF - Lots'!$P:$P,'MF - Lots'!$D:$D,B18)+SUMIFS('Equities - Lots'!$M:$M,'Equities - Lots'!$E:$E,B18)+IF(B18="Digital Assets",'Crypto - Lots'!K31,0) | E18: =IFERROR(D18/SUM($D$16:$D$21),0) | F18: =D18-C18 | H18: Global | I18: =SUMIFS('MF - Lots'!$O:$O,'MF - Lots'!$F:$F,H18)+SUMIFS('Equities - Lots'!$L:$L,'Equities - Lots'!$F:$F,H18)+IF(H18="Global",'Crypto - Lots'!J31,0) | J18: =SUMIFS('MF - Lots'!$P:$P,'MF - Lots'!$F:$F,H18)+SUMIFS('Equities - Lots'!$M:$M,'Equities - Lots'!$F:$F,H18)+IF(H18="Global",'Crypto - Lots'!K31,0) | K18: =IFERROR(J18/SUM($J$16:$J$23),0) | L18: =J18-I18
B19: Alternatives | C19: =SUMIFS('MF - Lots'!$O:$O,'MF - Lots'!$D:$D,B19)+SUMIFS('Equities - Lots'!$L:$L,'Equities - Lots'!$E:$E,B19)+IF(B19="Digital Assets",'Crypto - Lots'!J31,0) | D19: =SUMIFS('MF - Lots'!$P:$P,'MF - Lots'!$D:$D,B19)+SUMIFS('Equities - Lots'!$M:$M,'Equities - Lots'!$E:$E,B19)+IF(B19="Digital Assets",'Crypto - Lots'!K31,0) | E19: =IFERROR(D19/SUM($D$16:$D$21),0) | F19: =D19-C19 | H19: South Korea | I19: =SUMIFS('MF - Lots'!$O:$O,'MF - Lots'!$F:$F,H19)+SUMIFS('Equities - Lots'!$L:$L,'Equities - Lots'!$F:$F,H19)+IF(H19="Global",'Crypto - Lots'!J31,0) | J19: =SUMIFS('MF - Lots'!$P:$P,'MF - Lots'!$F:$F,H19)+SUMIFS('Equities - Lots'!$M:$M,'Equities - Lots'!$F:$F,H19)+IF(H19="Global",'Crypto - Lots'!K31,0) | K19: =IFERROR(J19/SUM($J$16:$J$23),0) | L19: =J19-I19
B20: Cash & Equivalents | C20: =SUMIFS('MF - Lots'!$O:$O,'MF - Lots'!$D:$D,B20)+SUMIFS('Equities - Lots'!$L:$L,'Equities - Lots'!$E:$E,B20)+IF(B20="Digital Assets",'Crypto - Lots'!J31,0) | D20: =SUMIFS('MF - Lots'!$P:$P,'MF - Lots'!$D:$D,B20)+SUMIFS('Equities - Lots'!$M:$M,'Equities - Lots'!$E:$E,B20)+IF(B20="Digital Assets",'Crypto - Lots'!K31,0) | E20: =IFERROR(D20/SUM($D$16:$D$21),0) | F20: =D20-C20 | H20: Vietnam | I20: =SUMIFS('MF - Lots'!$O:$O,'MF - Lots'!$F:$F,H20)+SUMIFS('Equities - Lots'!$L:$L,'Equities - Lots'!$F:$F,H20)+IF(H20="Global",'Crypto - Lots'!J31,0) | J20: =SUMIFS('MF - Lots'!$P:$P,'MF - Lots'!$F:$F,H20)+SUMIFS('Equities - Lots'!$M:$M,'Equities - Lots'!$F:$F,H20)+IF(H20="Global",'Crypto - Lots'!K31,0) | K20: =IFERROR(J20/SUM($J$16:$J$23),0) | L20: =J20-I20
B21: Digital Assets | C21: =SUMIFS('MF - Lots'!$O:$O,'MF - Lots'!$D:$D,B21)+SUMIFS('Equities - Lots'!$L:$L,'Equities - Lots'!$E:$E,B21)+IF(B21="Digital Assets",'Crypto - Lots'!J31,0) | D21: =SUMIFS('MF - Lots'!$P:$P,'MF - Lots'!$D:$D,B21)+SUMIFS('Equities - Lots'!$M:$M,'Equities - Lots'!$E:$E,B21)+IF(B21="Digital Assets",'Crypto - Lots'!K31,0) | E21: =IFERROR(D21/SUM($D$16:$D$21),0) | F21: =D21-C21 | H21: China | I21: =SUMIFS('MF - Lots'!$O:$O,'MF - Lots'!$F:$F,H21)+SUMIFS('Equities - Lots'!$L:$L,'Equities - Lots'!$F:$F,H21)+IF(H21="Global",'Crypto - Lots'!J31,0) | J21: =SUMIFS('MF - Lots'!$P:$P,'MF - Lots'!$F:$F,H21)+SUMIFS('Equities - Lots'!$M:$M,'Equities - Lots'!$F:$F,H21)+IF(H21="Global",'Crypto - Lots'!K31,0) | K21: =IFERROR(J21/SUM($J$16:$J$23),0) | L21: =J21-I21
B22: TOTAL | C22: =SUM(C16:C21) | D22: =SUM(D16:D21) | E22: =SUM(E16:E21) | F22: =SUM(F16:F21) | H22: Japan | I22: =SUMIFS('MF - Lots'!$O:$O,'MF - Lots'!$F:$F,H22)+SUMIFS('Equities - Lots'!$L:$L,'Equities - Lots'!$F:$F,H22)+IF(H22="Global",'Crypto - Lots'!J31,0) | J22: =SUMIFS('MF - Lots'!$P:$P,'MF - Lots'!$F:$F,H22)+SUMIFS('Equities - Lots'!$M:$M,'Equities - Lots'!$F:$F,H22)+IF(H22="Global",'Crypto - Lots'!K31,0) | K22: =IFERROR(J22/SUM($J$16:$J$23),0) | L22: =J22-I22
H23: Europe | I23: =SUMIFS('MF - Lots'!$O:$O,'MF - Lots'!$F:$F,H23)+SUMIFS('Equities - Lots'!$L:$L,'Equities - Lots'!$F:$F,H23)+IF(H23="Global",'Crypto - Lots'!J31,0) | J23: =SUMIFS('MF - Lots'!$P:$P,'MF - Lots'!$F:$F,H23)+SUMIFS('Equities - Lots'!$M:$M,'Equities - Lots'!$F:$F,H23)+IF(H23="Global",'Crypto - Lots'!K31,0) | K23: =IFERROR(J23/SUM($J$16:$J$23),0) | L23: =J23-I23
H24: TOTAL | I24: =SUM(I16:I23) | J24: =SUM(J16:J23) | K24: =SUM(K16:K23) | L24: =SUM(L16:L23)
B26: TAX STATUS BREAKDOWN | H26: TOP 10 HOLDINGS (by Current Value)
B27: Tax Status | C27: Invested | D27: Current Value | E27: % of Port | F27: P&L | H27: Rank | I27: Name | J27: Custodian | K27: Current Value | L27: % of Port | N27: Pool_Name | O27: Pool_Custodian | P27: Pool_Value
B28: Open-Ended | C28: =SUMIFS('MF - Lots'!$O:$O,'MF - Lots'!$G:$G,B28)+IF(B28="Taxable",'Equities - Lots'!L46+'Crypto - Lots'!J31,0) | D28: =SUMIFS('MF - Lots'!$P:$P,'MF - Lots'!$G:$G,B28)+IF(B28="Taxable",'Equities - Lots'!M46+'Crypto - Lots'!K31,0) | E28: =IFERROR(D28/SUM($D$28:$D$33),0) | F28: =D28-C28 | H28: 1 | I28: =IFERROR(INDEX($N$28:$N$120,MATCH(LARGE($P$28:$P$120,1),$P$28:$P$120,0)),"") | J28: =IFERROR(INDEX($O$28:$O$120,MATCH(LARGE($P$28:$P$120,1),$P$28:$P$120,0)),"") | K28: =LARGE($P$28:$P$120,1) | L28: =IFERROR(K28/$D$22,0) | N28: ='MF - by Fund'!B5 | O28: ='MF - by Fund'!C5 | P28: ='MF - by Fund'!K5
B29: RMF | C29: =SUMIFS('MF - Lots'!$O:$O,'MF - Lots'!$G:$G,B29)+IF(B29="Taxable",'Equities - Lots'!L46+'Crypto - Lots'!J31,0) | D29: =SUMIFS('MF - Lots'!$P:$P,'MF - Lots'!$G:$G,B29)+IF(B29="Taxable",'Equities - Lots'!M46+'Crypto - Lots'!K31,0) | E29: =IFERROR(D29/SUM($D$28:$D$33),0) | F29: =D29-C29 | H29: 2 | I29: =IFERROR(INDEX($N$28:$N$120,MATCH(LARGE($P$28:$P$120,2),$P$28:$P$120,0)),"") | J29: =IFERROR(INDEX($O$28:$O$120,MATCH(LARGE($P$28:$P$120,2),$P$28:$P$120,0)),"") | K29: =LARGE($P$28:$P$120,2) | L29: =IFERROR(K29/$D$22,0) | N29: ='MF - by Fund'!B6 | O29: ='MF - by Fund'!C6 | P29: ='MF - by Fund'!K6
B30: SSF | C30: =SUMIFS('MF - Lots'!$O:$O,'MF - Lots'!$G:$G,B30)+IF(B30="Taxable",'Equities - Lots'!L46+'Crypto - Lots'!J31,0) | D30: =SUMIFS('MF - Lots'!$P:$P,'MF - Lots'!$G:$G,B30)+IF(B30="Taxable",'Equities - Lots'!M46+'Crypto - Lots'!K31,0) | E30: =IFERROR(D30/SUM($D$28:$D$33),0) | F30: =D30-C30 | H30: 3 | I30: =IFERROR(INDEX($N$28:$N$120,MATCH(LARGE($P$28:$P$120,3),$P$28:$P$120,0)),"") | J30: =IFERROR(INDEX($O$28:$O$120,MATCH(LARGE($P$28:$P$120,3),$P$28:$P$120,0)),"") | K30: =LARGE($P$28:$P$120,3) | L30: =IFERROR(K30/$D$22,0) | N30: ='MF - by Fund'!B7 | O30: ='MF - by Fund'!C7 | P30: ='MF - by Fund'!K7
B31: Thai ESG | C31: =SUMIFS('MF - Lots'!$O:$O,'MF - Lots'!$G:$G,B31)+IF(B31="Taxable",'Equities - Lots'!L46+'Crypto - Lots'!J31,0) | D31: =SUMIFS('MF - Lots'!$P:$P,'MF - Lots'!$G:$G,B31)+IF(B31="Taxable",'Equities - Lots'!M46+'Crypto - Lots'!K31,0) | E31: =IFERROR(D31/SUM($D$28:$D$33),0) | F31: =D31-C31 | H31: 4 | I31: =IFERROR(INDEX($N$28:$N$120,MATCH(LARGE($P$28:$P$120,4),$P$28:$P$120,0)),"") | J31: =IFERROR(INDEX($O$28:$O$120,MATCH(LARGE($P$28:$P$120,4),$P$28:$P$120,0)),"") | K31: =LARGE($P$28:$P$120,4) | L31: =IFERROR(K31/$D$22,0) | N31: ='MF - by Fund'!B8 | O31: ='MF - by Fund'!C8 | P31: ='MF - by Fund'!K8
B32: LTF | C32: =SUMIFS('MF - Lots'!$O:$O,'MF - Lots'!$G:$G,B32)+IF(B32="Taxable",'Equities - Lots'!L46+'Crypto - Lots'!J31,0) | D32: =SUMIFS('MF - Lots'!$P:$P,'MF - Lots'!$G:$G,B32)+IF(B32="Taxable",'Equities - Lots'!M46+'Crypto - Lots'!K31,0) | E32: =IFERROR(D32/SUM($D$28:$D$33),0) | F32: =D32-C32 | H32: 5 | I32: =IFERROR(INDEX($N$28:$N$120,MATCH(LARGE($P$28:$P$120,5),$P$28:$P$120,0)),"") | J32: =IFERROR(INDEX($O$28:$O$120,MATCH(LARGE($P$28:$P$120,5),$P$28:$P$120,0)),"") | K32: =LARGE($P$28:$P$120,5) | L32: =IFERROR(K32/$D$22,0) | N32: ='MF - by Fund'!B9 | O32: ='MF - by Fund'!C9 | P32: ='MF - by Fund'!K9
B33: Taxable | C33: =SUMIFS('MF - Lots'!$O:$O,'MF - Lots'!$G:$G,B33)+IF(B33="Taxable",'Equities - Lots'!L46+'Crypto - Lots'!J31,0) | D33: =SUMIFS('MF - Lots'!$P:$P,'MF - Lots'!$G:$G,B33)+IF(B33="Taxable",'Equities - Lots'!M46+'Crypto - Lots'!K31,0) | E33: =IFERROR(D33/SUM($D$28:$D$33),0) | F33: =D33-C33 | H33: 6 | I33: =IFERROR(INDEX($N$28:$N$120,MATCH(LARGE($P$28:$P$120,6),$P$28:$P$120,0)),"") | J33: =IFERROR(INDEX($O$28:$O$120,MATCH(LARGE($P$28:$P$120,6),$P$28:$P$120,0)),"") | K33: =LARGE($P$28:$P$120,6) | L33: =IFERROR(K33/$D$22,0) | N33: ='MF - by Fund'!B10 | O33: ='MF - by Fund'!C10 | P33: ='MF - by Fund'!K10
B34: TOTAL | C34: =SUM(C28:C33) | D34: =SUM(D28:D33) | E34: =SUM(E28:E33) | F34: =SUM(F28:F33) | H34: 7 | I34: =IFERROR(INDEX($N$28:$N$120,MATCH(LARGE($P$28:$P$120,7),$P$28:$P$120,0)),"") | J34: =IFERROR(INDEX($O$28:$O$120,MATCH(LARGE($P$28:$P$120,7),$P$28:$P$120,0)),"") | K34: =LARGE($P$28:$P$120,7) | L34: =IFERROR(K34/$D$22,0) | N34: ='MF - by Fund'!B11 | O34: ='MF - by Fund'!C11 | P34: ='MF - by Fund'!K11
H35: 8 | I35: =IFERROR(INDEX($N$28:$N$120,MATCH(LARGE($P$28:$P$120,8),$P$28:$P$120,0)),"") | J35: =IFERROR(INDEX($O$28:$O$120,MATCH(LARGE($P$28:$P$120,8),$P$28:$P$120,0)),"") | K35: =LARGE($P$28:$P$120,8) | L35: =IFERROR(K35/$D$22,0) | N35: ='MF - by Fund'!B12 | O35: ='MF - by Fund'!C12 | P35: ='MF - by Fund'!K12
H36: 9 | I36: =IFERROR(INDEX($N$28:$N$120,MATCH(LARGE($P$28:$P$120,9),$P$28:$P$120,0)),"") | J36: =IFERROR(INDEX($O$28:$O$120,MATCH(LARGE($P$28:$P$120,9),$P$28:$P$120,0)),"") | K36: =LARGE($P$28:$P$120,9) | L36: =IFERROR(K36/$D$22,0) | N36: ='MF - by Fund'!B13 | O36: ='MF - by Fund'!C13 | P36: ='MF - by Fund'!K13
H37: 10 | I37: =IFERROR(INDEX($N$28:$N$120,MATCH(LARGE($P$28:$P$120,10),$P$28:$P$120,0)),"") | J37: =IFERROR(INDEX($O$28:$O$120,MATCH(LARGE($P$28:$P$120,10),$P$28:$P$120,0)),"") | K37: =LARGE($P$28:$P$120,10) | L37: =IFERROR(K37/$D$22,0) | N37: ='MF - by Fund'!B14 | O37: ='MF - by Fund'!C14 | P37: ='MF - by Fund'!K14
B39: THEME / SECTOR ALLOCATION (top themes) | N39: ='MF - by Fund'!B15 | O39: ='MF - by Fund'!C15 | P39: ='MF - by Fund'!K15
B40: Theme | C40: Invested | D40: Current Value | E40: % of Port | F40: P&L | N40: ='MF - by Fund'!B16 | O40: ='MF - by Fund'!C16 | P40: ='MF - by Fund'!K16
B41: US Large Cap | C41: =SUMIFS('MF - Lots'!$O:$O,'MF - Lots'!$E:$E,B41)+SUMIFS('Equities - Lots'!$L:$L,'Equities - Lots'!$G:$G,B41)+SUMIFS('Crypto - Lots'!$J:$J,'Crypto - Lots'!$E:$E,B41) | D41: =SUMIFS('MF - Lots'!$P:$P,'MF - Lots'!$E:$E,B41)+SUMIFS('Equities - Lots'!$M:$M,'Equities - Lots'!$G:$G,B41)+SUMIFS('Crypto - Lots'!$K:$K,'Crypto - Lots'!$E:$E,B41) | E41: =IFERROR(D41/$D$22,0) | F41: =D41-C41 | N41: ='MF - by Fund'!B17 | O41: ='MF - by Fund'!C17 | P41: ='MF - by Fund'!K17
B42: Korea | C42: =SUMIFS('MF - Lots'!$O:$O,'MF - Lots'!$E:$E,B42)+SUMIFS('Equities - Lots'!$L:$L,'Equities - Lots'!$G:$G,B42)+SUMIFS('Crypto - Lots'!$J:$J,'Crypto - Lots'!$E:$E,B42) | D42: =SUMIFS('MF - Lots'!$P:$P,'MF - Lots'!$E:$E,B42)+SUMIFS('Equities - Lots'!$M:$M,'Equities - Lots'!$G:$G,B42)+SUMIFS('Crypto - Lots'!$K:$K,'Crypto - Lots'!$E:$E,B42) | E42: =IFERROR(D42/$D$22,0) | F42: =D42-C42 | N42: ='MF - by Fund'!B18 | O42: ='MF - by Fund'!C18 | P42: ='MF - by Fund'!K18
B43: Thai Equity | C43: =SUMIFS('MF - Lots'!$O:$O,'MF - Lots'!$E:$E,B43)+SUMIFS('Equities - Lots'!$L:$L,'Equities - Lots'!$G:$G,B43)+SUMIFS('Crypto - Lots'!$J:$J,'Crypto - Lots'!$E:$E,B43) | D43: =SUMIFS('MF - Lots'!$P:$P,'MF - Lots'!$E:$E,B43)+SUMIFS('Equities - Lots'!$M:$M,'Equities - Lots'!$G:$G,B43)+SUMIFS('Crypto - Lots'!$K:$K,'Crypto - Lots'!$E:$E,B43) | E43: =IFERROR(D43/$D$22,0) | F43: =D43-C43 | N43: ='MF - by Fund'!B19 | O43: ='MF - by Fund'!C19 | P43: ='MF - by Fund'!K19
B44: Healthcare | C44: =SUMIFS('MF - Lots'!$O:$O,'MF - Lots'!$E:$E,B44)+SUMIFS('Equities - Lots'!$L:$L,'Equities - Lots'!$G:$G,B44)+SUMIFS('Crypto - Lots'!$J:$J,'Crypto - Lots'!$E:$E,B44) | D44: =SUMIFS('MF - Lots'!$P:$P,'MF - Lots'!$E:$E,B44)+SUMIFS('Equities - Lots'!$M:$M,'Equities - Lots'!$G:$G,B44)+SUMIFS('Crypto - Lots'!$K:$K,'Crypto - Lots'!$E:$E,B44) | E44: =IFERROR(D44/$D$22,0) | F44: =D44-C44 | N44: ='MF - by Fund'!B20 | O44: ='MF - by Fund'!C20 | P44: ='MF - by Fund'!K20
B45: Crypto (All) | C45: ='Crypto - Lots'!J31 | D45: ='Crypto - Lots'!K31 | E45: =IFERROR(D45/$D$22,0) | F45: =D45-C45 | N45: ='MF - by Fund'!B21 | O45: ='MF - by Fund'!C21 | P45: ='MF - by Fund'!K21
B46: Vietnam Equity | C46: =SUMIFS('MF - Lots'!$O:$O,'MF - Lots'!$E:$E,B46)+SUMIFS('Equities - Lots'!$L:$L,'Equities - Lots'!$G:$G,B46)+SUMIFS('Crypto - Lots'!$J:$J,'Crypto - Lots'!$E:$E,B46) | D46: =SUMIFS('MF - Lots'!$P:$P,'MF - Lots'!$E:$E,B46)+SUMIFS('Equities - Lots'!$M:$M,'Equities - Lots'!$G:$G,B46)+SUMIFS('Crypto - Lots'!$K:$K,'Crypto - Lots'!$E:$E,B46) | E46: =IFERROR(D46/$D$22,0) | F46: =D46-C46 | N46: ='MF - by Fund'!B22 | O46: ='MF - by Fund'!C22 | P46: ='MF - by Fund'!K22
B47: Thai Single Stock | C47: =SUMIFS('MF - Lots'!$O:$O,'MF - Lots'!$E:$E,B47)+SUMIFS('Equities - Lots'!$L:$L,'Equities - Lots'!$G:$G,B47)+SUMIFS('Crypto - Lots'!$J:$J,'Crypto - Lots'!$E:$E,B47) | D47: =SUMIFS('MF - Lots'!$P:$P,'MF - Lots'!$E:$E,B47)+SUMIFS('Equities - Lots'!$M:$M,'Equities - Lots'!$G:$G,B47)+SUMIFS('Crypto - Lots'!$K:$K,'Crypto - Lots'!$E:$E,B47) | E47: =IFERROR(D47/$D$22,0) | F47: =D47-C47 | N47: ='MF - by Fund'!B23 | O47: ='MF - by Fund'!C23 | P47: ='MF - by Fund'!K23
B48: Thai Balanced | C48: =SUMIFS('MF - Lots'!$O:$O,'MF - Lots'!$E:$E,B48)+SUMIFS('Equities - Lots'!$L:$L,'Equities - Lots'!$G:$G,B48)+SUMIFS('Crypto - Lots'!$J:$J,'Crypto - Lots'!$E:$E,B48) | D48: =SUMIFS('MF - Lots'!$P:$P,'MF - Lots'!$E:$E,B48)+SUMIFS('Equities - Lots'!$M:$M,'Equities - Lots'!$G:$G,B48)+SUMIFS('Crypto - Lots'!$K:$K,'Crypto - Lots'!$E:$E,B48) | E48: =IFERROR(D48/$D$22,0) | F48: =D48-C48 | N48: ='MF - by Fund'!B24 | O48: ='MF - by Fund'!C24 | P48: ='MF - by Fund'!K24
...

Sheet Weekly Snapshot
B2: WEEKLY SNAPSHOT LOG
B3: Row 5 shows the live current-week snapshot. Each Friday, copy row 5 (values only) into the next empty row below to preserve history.
B4: Date | C4: Total Value | D4: Total Invested | E4: Unrealized P&L | F4: P&L % | G4: MF Value | H4: EQ Value | I4: Crypto Value | J4: USDTHB | K4: Notes
B5: =AsOfDate | C5: ='MF - Lots'!P165+'Equities - Lots'!M46+'Crypto - Lots'!K31 | D5: ='MF - Lots'!O165+'Equities - Lots'!L46+'Crypto - Lots'!J31 | E5: =C5-D5 | F5: =IFERROR(E5/D5,0) | G5: ='MF - Lots'!P165 | H5: ='Equities - Lots'!M46 | I5: ='Crypto - Lots'!K31 | J5: =FXRate | K5: Live (current workbook state)

Sheet FX & Assumptions
B2: FX & ASSUMPTIONS
B4: Item | C4: Value | D4: Notes
B5: As-of Date | C5: 46023 | D5: Reporting date — updated weekly.
B6: USD / THB Spot | C6: 33 | D6: Enter weekly USD/THB spot (or let the auto-fetch fill it).
B7: Reporting Currency | C7: THB | D7: Base currency for all totals.
B8: Total Lots (MF / EQ / Crypto) | C8: 0 / 0 / 0 | D8: Record count from source file.

Sheet Prices
A2: PRICES — Weekly Update Sheet (update yellow "Current Price / NAV" column every week)
A4: Key (auto) | B4: Type | C4: Name | D4: Custodian | E4: Current Price / NAV | F4: Currency | G4: Last Update | H4: CHECK
A5: =B5&"|"&C5&"|"&D5
A6: =B6&"|"&C6&"|"&D6
A7: =B7&"|"&C7&"|"&D7
A8: =B8&"|"&C8&"|"&D8
A9: =B9&"|"&C9&"|"&D9
A10: =B10&"|"&C10&"|"&D10
A11: =B11&"|"&C11&"|"&D11
A12: =B12&"|"&C12&"|"&D12
A13: =B13&"|"&C13&"|"&D13
A14: =B14&"|"&C14&"|"&D14
A15: =B15&"|"&C15&"|"&D15
A16: =B16&"|"&C16&"|"&D16
... A96: =B96&"|"&C96&"|"&D96

Sheet MF - Lots
A2: MUTUAL FUND HOLDINGS — LOT LEVEL
A4: # | B4: AMC | C4: Fund Name | D4: Asset Class | E4: Theme | F4: Geography | G4: Tax Status | H4: Purchase Date | I4: Purch. Yr | J4: Sellable Yr | K4: Yrs Held | L4: Units | M4: Avg Cost | N4: Current NAV | O4: Initial Inv (฿) | P4: Current Value (฿) | Q4: Unrealized P&L (฿) | R4: P&L % | S4: Note
A5: 1 | D5: =IFERROR(INDEX(Reference!$E:$E,MATCH("Mutual Fund|"&C5&"|"&B5,Reference!$A:$A,0)),"") | E5: =IFERROR(INDEX(Reference!$H:$H,MATCH("Mutual Fund|"&C5&"|"&B5,Reference!$A:$A,0)),"") | F5: =IFERROR(INDEX(Reference!$G:$G,MATCH("Mutual Fund|"&C5&"|"&B5,Reference!$A:$A,0)),"") | G5: =IFERROR(INDEX(Reference!$I:$I,MATCH("Mutual Fund|"&C5&"|"&B5,Reference!$A:$A,0)),"") | K5: =IFERROR(IF(H5="","",(AsOfDate-H5)/365.25),"") | N5: =IFERROR(INDEX(Prices!$E:$E,MATCH("Mutual Fund|"&C5&"|"&B5,Prices!$A:$A,0)),0) | P5: =L5*N5 | Q5: =P5-O5 | R5: =IFERROR(Q5/O5,0)
A6: 2 | D6: =IFERROR(INDEX(Reference!$E:$E,MATCH("Mutual Fund|"&C6&"|"&B6,Reference!$A:$A,0)),"") | E6: =IFERROR(INDEX(Reference!$H:$H,MATCH("Mutual Fund|"&C6&"|"&B6,Reference!$A:$A,0)),"") | F6: =IFERROR(INDEX(Reference!$G:$G,MATCH("Mutual Fund|"&C6&"|"&B6,Reference!$A:$A,0)),"") | G6: =IFERROR(INDEX(Reference!$I:$I,MATCH("Mutual Fund|"&C6&"|"&B6,Reference!$A:$A,0)),"") | K6: =IFERROR(IF(H6="","",(AsOfDate-H6)/365.25),"") | N6: =IFERROR(INDEX(Prices!$E:$E,MATCH("Mutual Fund|"&C6&"|"&B6,Prices!$A:$A,0)),0) | P6: =L6*N6 | Q6: =P6-O6 | R6: =IFERROR(Q6/O6,0)
A7: 3 | D7: =IFERROR(INDEX(Reference!$E:$E,MATCH("Mutual Fund|"&C7&"|"&B7,Reference!$A:$A,0)),"") | E7: =IFERROR(INDEX(Reference!$H:$H,MATCH("Mutual Fund|"&C7&"|"&B7,Reference!$A:$A,0)),"") | F7: =IFERROR(INDEX(Reference!$G:$G,MATCH("Mutual Fund|"&C7&"|"&B7,Reference!$A:$A,0)),"") | G7: =IFERROR(INDEX(Reference!$I:$I,MATCH("Mutual Fund|"&C7&"|"&B7,Reference!$A:$A,0)),"") | K7: =IFERROR(IF(H7="","",(AsOfDate-H7)/365.25),"") | N7: =IFERROR(INDEX(Prices!$E:$E,MATCH("Mutual Fund|"&C7&"|"&B7,Prices!$A:$A,0)),0) | P7: =L7*N7 | Q7: =P7-O7 | R7: =IFERROR(Q7/O7,0)
A8: 4 | D8: =IFERROR(INDEX(Reference!$E:$E,MATCH("Mutual Fund|"&C8&"|"&B8,Reference!$A:$A,0)),"") | E8: =IFERROR(INDEX(Reference!$H:$H,MATCH("Mutual Fund|"&C8&"|"&B8,Reference!$A:$A,0)),"") | F8: =IFERROR(INDEX(Reference!$G:$G,MATCH("Mutual Fund|"&C8&"|"&B8,Reference!$A:$A,0)),"") | G8: =IFERROR(INDEX(Reference!$I:$I,MATCH("Mutual Fund|"&C8&"|"&B8,Reference!$A:$A,0)),"") | K8: =IFERROR(IF(H8="","",(AsOfDate-H8)/365.25),"") | N8: =IFERROR(INDEX(Prices!$E:$E,MATCH("Mutual Fund|"&C8&"|"&B8,Prices!$A:$A,0)),0) | P8: =L8*N8 | Q8: =P8-O8 | R8: =IFERROR(Q8/O8,0)
A9: 5 | D9: =IFERROR(INDEX(Reference!$E:$E,MATCH("Mutual Fund|"&C9&"|"&B9,Reference!$A:$A,0)),"") | E9: =IFERROR(INDEX(Reference!$H:$H,MATCH("Mutual Fund|"&C9&"|"&B9,Reference!$A:$A,0)),"") | F9: =IFERROR(INDEX(Reference!$G:$G,MATCH("Mutual Fund|"&C9&"|"&B9,Reference!$A:$A,0)),"") | G9: =IFERROR(INDEX(Reference!$I:$I,MATCH("Mutual Fund|"&C9&"|"&B9,Reference!$A:$A,0)),"") | K9: =IFERROR(IF(H9="","",(AsOfDate-H9)/365.25),"") | N9: =IFERROR(INDEX(Prices!$E:$E,MATCH("Mutual Fund|"&C9&"|"&B9,Prices!$A:$A,0)),0) | P9: =L9*N9 | Q9: =P9-O9 | R9: =IFERROR(Q9/O9,0)
A10: 6 | D10: =IFERROR(INDEX(Reference!$E:$E,MATCH("Mutual Fund|"&C10&"|"&B10,Reference!$A:$A,0)),"") | E10: =IFERROR(INDEX(Reference!$H:$H,MATCH("Mutual Fund|"&C10&"|"&B10,Reference!$A:$A,0)),"") | F10: =IFERROR(INDEX(Reference!$G:$G,MATCH("Mutual Fund|"&C10&"|"&B10,Reference!$A:$A,0)),"") | G10: =IFERROR(INDEX(Reference!$I:$I,MATCH("Mutual Fund|"&C10&"|"&B10,Reference!$A:$A,0)),"") | K10: =IFERROR(IF(H10="","",(AsOfDate-H10)/365.25),"") | N10: =IFERROR(INDEX(Prices!$E:$E,MATCH("Mutual Fund|"&C10&"|"&B10,Prices!$A:$A,0)),0) | P10: =L10*N10 | Q10: =P10-O10 | R10: =IFERROR(Q10/O10,0)
A11: 7 | D11: =IFERROR(INDEX(Reference!$E:$E,MATCH("Mutual Fund|"&C11&"|"&B11,Reference!$A:$A,0)),"") | E11: =IFERROR(INDEX(Reference!$H:$H,MATCH("Mutual Fund|"&C11&"|"&B11,Reference!$A:$A,0)),"") | F11: =IFERROR(INDEX(Reference!$G:$G,MATCH("Mutual Fund|"&C11&"|"&B11,Reference!$A:$A,0)),"") | G11: =IFERROR(INDEX(Reference!$I:$I,MATCH("Mutual Fund|"&C11&"|"&B11,Reference!$A:$A,0)),"") | K11: =IFERROR(IF(H11="","",(AsOfDate-H11)/365.25),"") | N11: =IFERROR(INDEX(Prices!$E:$E,MATCH("Mutual Fund|"&C11&"|"&B11,Prices!$A:$A,0)),0) | P11: =L11*N11 | Q11: =P11-O11 | R11: =IFERROR(Q11/O11,0)
A12: 8 | D12: =IFERROR(INDEX(Reference!$E:$E,MATCH("Mutual Fund|"&C12&"|"&B12,Reference!$A:$A,0)),"") | E12: =IFERROR(INDEX(Reference!$H:$H,MATCH("Mutual Fund|"&C12&"|"&B12,Reference!$A:$A,0)),"") | F12: =IFERROR(INDEX(Reference!$G:$G,MATCH("Mutual Fund|"&C12&"|"&B12,Reference!$A:$A,0)),"") | G12: =IFERROR(INDEX(Reference!$I:$I,MATCH("Mutual Fund|"&C12&"|"&B12,Reference!$A:$A,0)),"") | K12: =IFERROR(IF(H12="","",(AsOfDate-H12)/365.25),"") | N12: =IFERROR(INDEX(Prices!$E:$E,MATCH("Mutual Fund|"&C12&"|"&B12,Prices!$A:$A,0)),0) | P12: =L12*N12 | Q12: =P12-O12 | R12: =IFERROR(Q12/O12,0)
A13: 9 | D13: =IFERROR(INDEX(Reference!$E:$E,MATCH("Mutual Fund|"&C13&"|"&B13,Reference!$A:$A,0)),"") | E13: =IFERROR(INDEX(Reference!$H:$H,MATCH("Mutual Fund|"&C13&"|"&B13,Reference!$A:$A,0)),"") | F13: =IFERROR(INDEX(Reference!$G:$G,MATCH("Mutual Fund|"&C13&"|"&B13,Reference!$A:$A,0)),"") | G13: =IFERROR(INDEX(Reference!$I:$I,MATCH("Mutual Fund|"&C13&"|"&B13,Reference!$A:$A,0)),"") | K13: =IFERROR(IF(H13="","",(AsOfDate-H13)/365.25),"") | N13: =IFERROR(INDEX(Prices!$E:$E,MATCH("Mutual Fund|"&C13&"|"&B13,Prices!$A:$A,0)),0) | P13: =L13*N13 | Q13: =P13-O13 | R13: =IFERROR(Q13/O13,0)
A14: 10 | D14: =IFERROR(INDEX(Reference!$E:$E,MATCH("Mutual Fund|"&C14&"|"&B14,Reference!$A:$A,0)),"") | E14: =IFERROR(INDEX(Reference!$H:$H,MATCH("Mutual Fund|"&C14&"|"&B14,Reference!$A:$A,0)),"") | F14: =IFERROR(INDEX(Reference!$G:$G,MATCH("Mutual Fund|"&C14&"|"&B14,Reference!$A:$A,0)),"") | G14: =IFERROR(INDEX(Reference!$I:$I,MATCH("Mutual Fund|"&C14&"|"&B14,Reference!$A:$A,0)),"") | K14: =IFERROR(IF(H14="","",(AsOfDate-H14)/365.25),"") | N14: =IFERROR(INDEX(Prices!$E:$E,MATCH("Mutual Fund|"&C14&"|"&B14,Prices!$A:$A,0)),0) | P14: =L14*N14 | Q14: =P14-O14 | R14: =IFERROR(Q14/O14,0)
A15: 11 | D15: =IFERROR(INDEX(Reference!$E:$E,MATCH("Mutual Fund|"&C15&"|"&B15,Reference!$A:$A,0)),"") | E15: =IFERROR(INDEX(Reference!$H:$H,MATCH("Mutual Fund|"&C15&"|"&B15,Reference!$A:$A,0)),"") | F15: =IFERROR(INDEX(Reference!$G:$G,MATCH("Mutual Fund|"&C15&"|"&B15,Reference!$A:$A,0)),"") | G15: =IFERROR(INDEX(Reference!$I:$I,MATCH("Mutual Fund|"&C15&"|"&B15,Reference!$A:$A,0)),"") | K15: =IFERROR(IF(H15="","",(AsOfDate-H15)/365.25),"") | N15: =IFERROR(INDEX(Prices!$E:$E,MATCH("Mutual Fund|"&C15&"|"&B15,Prices!$A:$A,0)),0) | P15: =L15*N15 | Q15: =P15-O15 | R15: =IFERROR(Q15/O15,0)
A16: 12 | D16: =IFERROR(INDEX(Reference!$E:$E,MATCH("Mutual Fund|"&C16&"|"&B16,Reference!$A:$A,0)),"") | E16: =IFERROR(INDEX(Reference!$H:$H,MATCH("Mutual Fund|"&C16&"|"&B16,Reference!$A:$A,0)),"") | F16: =IFERROR(INDEX(Reference!$G:$G,MATCH("Mutual Fund|"&C16&"|"&B16,Reference!$A:$A,0)),"") | G16: =IFERROR(INDEX(Reference!$I:$I,MATCH("Mutual Fund|"&C16&"|"&B16,Reference!$A:$A,0)),"") | K16: =IFERROR(IF(H16="","",(AsOfDate-H16)/365.25),"") | N16: =IFERROR(INDEX(Prices!$E:$E,MATCH("Mutual Fund|"&C16&"|"&B16,Prices!$A:$A,0)),0) | P16: =L16*N16 | Q16: =P16-O16 | R16: =IFERROR(Q16/O16,0)
... A164: 160 | D164: =IFERROR(INDEX(Reference!$E:$E,MATCH("Mutual Fund|"&C164&"|"&B164,Reference!$A:$A,0)),"") | E164: =IFERROR(INDEX(Reference!$H:$H,MATCH("Mutual Fund|"&C164&"|"&B164,Reference!$A:$A,0)),"") | F164: =IFERROR(INDEX(Reference!$G:$G,MATCH("Mutual Fund|"&C164&"|"&B164,Reference!$A:$A,0)),"") | G164: =IFERROR(INDEX(Reference!$I:$I,MATCH("Mutual Fund|"&C164&"|"&B164,Reference!$A:$A,0)),"") | K164: =IFERROR(IF(H164="","",(AsOfDate-H164)/365.25),"") | N164: =IFERROR(INDEX(Prices!$E:$E,MATCH("Mutual Fund|"&C164&"|"&B164,Prices!$A:$A,0)),0) | P164: =L164*N164 | Q164: =P164-O164 | R164: =IFERROR(Q164/O164,0)
A165: TOTAL | O165: =SUM(O5:O164) | P165: =SUM(P5:P164) | Q165: =SUM(Q5:Q164) | R165: =IFERROR(Q165/O165,0)

Sheet MF - by Fund
A2: MUTUAL FUND — ROLLUP BY FUND
A4: # | B4: Fund Name | C4: AMC | D4: Asset Class | E4: Theme | F4: Geography | G4: Tax Status | H4: Lots | I4: Units | J4: Initial Inv (฿) | K4: Current Value (฿) | L4: Unrealized P&L (฿) | M4: P&L %
A5: 1 | D5: =IFERROR(INDEX(Reference!$E:$E,MATCH("Mutual Fund|"&B5&"|"&C5,Reference!$A:$A,0)),"") | E5: =IFERROR(INDEX(Reference!$H:$H,MATCH("Mutual Fund|"&B5&"|"&C5,Reference!$A:$A,0)),"") | F5: =IFERROR(INDEX(Reference!$G:$G,MATCH("Mutual Fund|"&B5&"|"&C5,Reference!$A:$A,0)),"") | G5: =IFERROR(INDEX(Reference!$I:$I,MATCH("Mutual Fund|"&B5&"|"&C5,Reference!$A:$A,0)),"") | H5: =COUNTIFS('MF - Lots'!$C:$C,B5) | I5: =SUMIFS('MF - Lots'!$L:$L,'MF - Lots'!$C:$C,B5) | J5: =SUMIFS('MF - Lots'!$O:$O,'MF - Lots'!$C:$C,B5) | K5: =SUMIFS('MF - Lots'!$P:$P,'MF - Lots'!$C:$C,B5) | L5: =K5-J5 | M5: =IFERROR(L5/J5,0)
A6: 2 | D6: =IFERROR(INDEX(Reference!$E:$E,MATCH("Mutual Fund|"&B6&"|"&C6,Reference!$A:$A,0)),"") | E6: =IFERROR(INDEX(Reference!$H:$H,MATCH("Mutual Fund|"&B6&"|"&C6,Reference!$A:$A,0)),"") | F6: =IFERROR(INDEX(Reference!$G:$G,MATCH("Mutual Fund|"&B6&"|"&C6,Reference!$A:$A,0)),"") | G6: =IFERROR(INDEX(Reference!$I:$I,MATCH("Mutual Fund|"&B6&"|"&C6,Reference!$A:$A,0)),"") | H6: =COUNTIFS('MF - Lots'!$C:$C,B6) | I6: =SUMIFS('MF - Lots'!$L:$L,'MF - Lots'!$C:$C,B6) | J6: =SUMIFS('MF - Lots'!$O:$O,'MF - Lots'!$C:$C,B6) | K6: =SUMIFS('MF - Lots'!$P:$P,'MF - Lots'!$C:$C,B6) | L6: =K6-J6 | M6: =IFERROR(L6/J6,0)
A7: 3 | D7: =IFERROR(INDEX(Reference!$E:$E,MATCH("Mutual Fund|"&B7&"|"&C7,Reference!$A:$A,0)),"") | E7: =IFERROR(INDEX(Reference!$H:$H,MATCH("Mutual Fund|"&B7&"|"&C7,Reference!$A:$A,0)),"") | F7: =IFERROR(INDEX(Reference!$G:$G,MATCH("Mutual Fund|"&B7&"|"&C7,Reference!$A:$A,0)),"") | G7: =IFERROR(INDEX(Reference!$I:$I,MATCH("Mutual Fund|"&B7&"|"&C7,Reference!$A:$A,0)),"") | H7: =COUNTIFS('MF - Lots'!$C:$C,B7) | I7: =SUMIFS('MF - Lots'!$L:$L,'MF - Lots'!$C:$C,B7) | J7: =SUMIFS('MF - Lots'!$O:$O,'MF - Lots'!$C:$C,B7) | K7: =SUMIFS('MF - Lots'!$P:$P,'MF - Lots'!$C:$C,B7) | L7: =K7-J7 | M7: =IFERROR(L7/J7,0)
A8: 4 | D8: =IFERROR(INDEX(Reference!$E:$E,MATCH("Mutual Fund|"&B8&"|"&C8,Reference!$A:$A,0)),"") | E8: =IFERROR(INDEX(Reference!$H:$H,MATCH("Mutual Fund|"&B8&"|"&C8,Reference!$A:$A,0)),"") | F8: =IFERROR(INDEX(Reference!$G:$G,MATCH("Mutual Fund|"&B8&"|"&C8,Reference!$A:$A,0)),"") | G8: =IFERROR(INDEX(Reference!$I:$I,MATCH("Mutual Fund|"&B8&"|"&C8,Reference!$A:$A,0)),"") | H8: =COUNTIFS('MF - Lots'!$C:$C,B8) | I8: =SUMIFS('MF - Lots'!$L:$L,'MF - Lots'!$C:$C,B8) | J8: =SUMIFS('MF - Lots'!$O:$O,'MF - Lots'!$C:$C,B8) | K8: =SUMIFS('MF - Lots'!$P:$P,'MF - Lots'!$C:$C,B8) | L8: =K8-J8 | M8: =IFERROR(L8/J8,0)
A9: 5 | D9: =IFERROR(INDEX(Reference!$E:$E,MATCH("Mutual Fund|"&B9&"|"&C9,Reference!$A:$A,0)),"") | E9: =IFERROR(INDEX(Reference!$H:$H,MATCH("Mutual Fund|"&B9&"|"&C9,Reference!$A:$A,0)),"") | F9: =IFERROR(INDEX(Reference!$G:$G,MATCH("Mutual Fund|"&B9&"|"&C9,Reference!$A:$A,0)),"") | G9: =IFERROR(INDEX(Reference!$I:$I,MATCH("Mutual Fund|"&B9&"|"&C9,Reference!$A:$A,0)),"") | H9: =COUNTIFS('MF - Lots'!$C:$C,B9) | I9: =SUMIFS('MF - Lots'!$L:$L,'MF - Lots'!$C:$C,B9) | J9: =SUMIFS('MF - Lots'!$O:$O,'MF - Lots'!$C:$C,B9) | K9: =SUMIFS('MF - Lots'!$P:$P,'MF - Lots'!$C:$C,B9) | L9: =K9-J9 | M9: =IFERROR(L9/J9,0)
A10: 6 | D10: =IFERROR(INDEX(Reference!$E:$E,MATCH("Mutual Fund|"&B10&"|"&C10,Reference!$A:$A,0)),"") | E10: =IFERROR(INDEX(Reference!$H:$H,MATCH("Mutual Fund|"&B10&"|"&C10,Reference!$A:$A,0)),"") | F10: =IFERROR(INDEX(Reference!$G:$G,MATCH("Mutual Fund|"&B10&"|"&C10,Reference!$A:$A,0)),"") | G10: =IFERROR(INDEX(Reference!$I:$I,MATCH("Mutual Fund|"&B10&"|"&C10,Reference!$A:$A,0)),"") | H10: =COUNTIFS('MF - Lots'!$C:$C,B10) | I10: =SUMIFS('MF - Lots'!$L:$L,'MF - Lots'!$C:$C,B10) | J10: =SUMIFS('MF - Lots'!$O:$O,'MF - Lots'!$C:$C,B10) | K10: =SUMIFS('MF - Lots'!$P:$P,'MF - Lots'!$C:$C,B10) | L10: =K10-J10 | M10: =IFERROR(L10/J10,0)
A11: 7 | D11: =IFERROR(INDEX(Reference!$E:$E,MATCH("Mutual Fund|"&B11&"|"&C11,Reference!$A:$A,0)),"") | E11: =IFERROR(INDEX(Reference!$H:$H,MATCH("Mutual Fund|"&B11&"|"&C11,Reference!$A:$A,0)),"") | F11: =IFERROR(INDEX(Reference!$G:$G,MATCH("Mutual Fund|"&B11&"|"&C11,Reference!$A:$A,0)),"") | G11: =IFERROR(INDEX(Reference!$I:$I,MATCH("Mutual Fund|"&B11&"|"&C11,Reference!$A:$A,0)),"") | H11: =COUNTIFS('MF - Lots'!$C:$C,B11) | I11: =SUMIFS('MF - Lots'!$L:$L,'MF - Lots'!$C:$C,B11) | J11: =SUMIFS('MF - Lots'!$O:$O,'MF - Lots'!$C:$C,B11) | K11: =SUMIFS('MF - Lots'!$P:$P,'MF - Lots'!$C:$C,B11) | L11: =K11-J11 | M11: =IFERROR(L11/J11,0)
A12: 8 | D12: =IFERROR(INDEX(Reference!$E:$E,MATCH("Mutual Fund|"&B12&"|"&C12,Reference!$A:$A,0)),"") | E12: =IFERROR(INDEX(Reference!$H:$H,MATCH("Mutual Fund|"&B12&"|"&C12,Reference!$A:$A,0)),"") | F12: =IFERROR(INDEX(Reference!$G:$G,MATCH("Mutual Fund|"&B12&"|"&C12,Reference!$A:$A,0)),"") | G12: =IFERROR(INDEX(Reference!$I:$I,MATCH("Mutual Fund|"&B12&"|"&C12,Reference!$A:$A,0)),"") | H12: =COUNTIFS('MF - Lots'!$C:$C,B12) | I12: =SUMIFS('MF - Lots'!$L:$L,'MF - Lots'!$C:$C,B12) | J12: =SUMIFS('MF - Lots'!$O:$O,'MF - Lots'!$C:$C,B12) | K12: =SUMIFS('MF - Lots'!$P:$P,'MF - Lots'!$C:$C,B12) | L12: =K12-J12 | M12: =IFERROR(L12/J12,0)
A13: 9 | D13: =IFERROR(INDEX(Reference!$E:$E,MATCH("Mutual Fund|"&B13&"|"&C13,Reference!$A:$A,0)),"") | E13: =IFERROR(INDEX(Reference!$H:$H,MATCH("Mutual Fund|"&B13&"|"&C13,Reference!$A:$A,0)),"") | F13: =IFERROR(INDEX(Reference!$G:$G,MATCH("Mutual Fund|"&B13&"|"&C13,Reference!$A:$A,0)),"") | G13: =IFERROR(INDEX(Reference!$I:$I,MATCH("Mutual Fund|"&B13&"|"&C13,Reference!$A:$A,0)),"") | H13: =COUNTIFS('MF - Lots'!$C:$C,B13) | I13: =SUMIFS('MF - Lots'!$L:$L,'MF - Lots'!$C:$C,B13) | J13: =SUMIFS('MF - Lots'!$O:$O,'MF - Lots'!$C:$C,B13) | K13: =SUMIFS('MF - Lots'!$P:$P,'MF - Lots'!$C:$C,B13) | L13: =K13-J13 | M13: =IFERROR(L13/J13,0)
A14: 10 | D14: =IFERROR(INDEX(Reference!$E:$E,MATCH("Mutual Fund|"&B14&"|"&C14,Reference!$A:$A,0)),"") | E14: =IFERROR(INDEX(Reference!$H:$H,MATCH("Mutual Fund|"&B14&"|"&C14,Reference!$A:$A,0)),"") | F14: =IFERROR(INDEX(Reference!$G:$G,MATCH("Mutual Fund|"&B14&"|"&C14,Reference!$A:$A,0)),"") | G14: =IFERROR(INDEX(Reference!$I:$I,MATCH("Mutual Fund|"&B14&"|"&C14,Reference!$A:$A,0)),"") | H14: =COUNTIFS('MF - Lots'!$C:$C,B14) | I14: =SUMIFS('MF - Lots'!$L:$L,'MF - Lots'!$C:$C,B14) | J14: =SUMIFS('MF - Lots'!$O:$O,'MF - Lots'!$C:$C,B14) | K14: =SUMIFS('MF - Lots'!$P:$P,'MF - Lots'!$C:$C,B14) | L14: =K14-J14 | M14: =IFERROR(L14/J14,0)
A15: 11 | D15: =IFERROR(INDEX(Reference!$E:$E,MATCH("Mutual Fund|"&B15&"|"&C15,Reference!$A:$A,0)),"") | E15: =IFERROR(INDEX(Reference!$H:$H,MATCH("Mutual Fund|"&B15&"|"&C15,Reference!$A:$A,0)),"") | F15: =IFERROR(INDEX(Reference!$G:$G,MATCH("Mutual Fund|"&B15&"|"&C15,Reference!$A:$A,0)),"") | G15: =IFERROR(INDEX(Reference!$I:$I,MATCH("Mutual Fund|"&B15&"|"&C15,Reference!$A:$A,0)),"") | H15: =COUNTIFS('MF - Lots'!$C:$C,B15) | I15: =SUMIFS('MF - Lots'!$L:$L,'MF - Lots'!$C:$C,B15) | J15: =SUMIFS('MF - Lots'!$O:$O,'MF - Lots'!$C:$C,B15) | K15: =SUMIFS('MF - Lots'!$P:$P,'MF - Lots'!$C:$C,B15) | L15: =K15-J15 | M15: =IFERROR(L15/J15,0)
A16: 12 | D16: =IFERROR(INDEX(Reference!$E:$E,MATCH("Mutual Fund|"&B16&"|"&C16,Reference!$A:$A,0)),"") | E16: =IFERROR(INDEX(Reference!$H:$H,MATCH("Mutual Fund|"&B16&"|"&C16,Reference!$A:$A,0)),"") | F16: =IFERROR(INDEX(Reference!$G:$G,MATCH("Mutual Fund|"&B16&"|"&C16,Reference!$A:$A,0)),"") | G16: =IFERROR(INDEX(Reference!$I:$I,MATCH("Mutual Fund|"&B16&"|"&C16,Reference!$A:$A,0)),"") | H16: =COUNTIFS('MF - Lots'!$C:$C,B16) | I16: =SUMIFS('MF - Lots'!$L:$L,'MF - Lots'!$C:$C,B16) | J16: =SUMIFS('MF - Lots'!$O:$O,'MF - Lots'!$C:$C,B16) | K16: =SUMIFS('MF - Lots'!$P:$P,'MF - Lots'!$C:$C,B16) | L16: =K16-J16 | M16: =IFERROR(L16/J16,0)
... A36: 32 | D36: =IFERROR(INDEX(Reference!$E:$E,MATCH("Mutual Fund|"&B36&"|"&C36,Reference!$A:$A,0)),"") | E36: =IFERROR(INDEX(Reference!$H:$H,MATCH("Mutual Fund|"&B36&"|"&C36,Reference!$A:$A,0)),"") | F36: =IFERROR(INDEX(Reference!$G:$G,MATCH("Mutual Fund|"&B36&"|"&C36,Reference!$A:$A,0)),"") | G36: =IFERROR(INDEX(Reference!$I:$I,MATCH("Mutual Fund|"&B36&"|"&C36,Reference!$A:$A,0)),"") | H36: =COUNTIFS('MF - Lots'!$C:$C,B36) | I36: =SUMIFS('MF - Lots'!$L:$L,'MF - Lots'!$C:$C,B36) | J36: =SUMIFS('MF - Lots'!$O:$O,'MF - Lots'!$C:$C,B36) | K36: =SUMIFS('MF - Lots'!$P:$P,'MF - Lots'!$C:$C,B36) | L36: =K36-J36 | M36: =IFERROR(L36/J36,0)
A37: TOTAL | H37: =SUM(H5:H36) | J37: =SUM(J5:J36) | K37: =SUM(K5:K36) | L37: =SUM(L5:L36) | M37: =IFERROR(L37/J37,0)

Sheet Equities - Lots
A2: EQUITIES — LOT LEVEL (Thai + US + ETF)
A4: # | B4: Broker | C4: Ticker | D4: Ccy | E4: Asset Class | F4: Geography | G4: Theme | H4: Shares | I4: Avg Cost (nat.) | J4: Mkt Price (nat.) | K4: FX | L4: Initial Inv (฿) | M4: Current Value (฿) | N4: Unrealized P&L (฿) | O4: P&L % | P4: Note
A5: 1 | E5: =IFERROR(INDEX(Reference!$E:$E,MATCH("Equity|"&C5&"|"&B5,Reference!$A:$A,0)),"") | F5: =IFERROR(INDEX(Reference!$G:$G,MATCH("Equity|"&C5&"|"&B5,Reference!$A:$A,0)),"") | G5: =IFERROR(INDEX(Reference!$H:$H,MATCH("Equity|"&C5&"|"&B5,Reference!$A:$A,0)),"") | J5: =IFERROR(INDEX(Prices!$E:$E,MATCH("Equity|"&C5&"|"&B5,Prices!$A:$A,0)),0) | K5: =IF(D5="THB",1,FXRate) | L5: =IFERROR(H5*I5*K5,0) | M5: =IFERROR(H5*J5*K5,0) | N5: =M5-L5 | O5: =IFERROR(N5/L5,0)
A6: 2 | E6: =IFERROR(INDEX(Reference!$E:$E,MATCH("Equity|"&C6&"|"&B6,Reference!$A:$A,0)),"") | F6: =IFERROR(INDEX(Reference!$G:$G,MATCH("Equity|"&C6&"|"&B6,Reference!$A:$A,0)),"") | G6: =IFERROR(INDEX(Reference!$H:$H,MATCH("Equity|"&C6&"|"&B6,Reference!$A:$A,0)),"") | J6: =IFERROR(INDEX(Prices!$E:$E,MATCH("Equity|"&C6&"|"&B6,Prices!$A:$A,0)),0) | K6: =IF(D6="THB",1,FXRate) | L6: =IFERROR(H6*I6*K6,0) | M6: =IFERROR(H6*J6*K6,0) | N6: =M6-L6 | O6: =IFERROR(N6/L6,0)
A7: 3 | E7: =IFERROR(INDEX(Reference!$E:$E,MATCH("Equity|"&C7&"|"&B7,Reference!$A:$A,0)),"") | F7: =IFERROR(INDEX(Reference!$G:$G,MATCH("Equity|"&C7&"|"&B7,Reference!$A:$A,0)),"") | G7: =IFERROR(INDEX(Reference!$H:$H,MATCH("Equity|"&C7&"|"&B7,Reference!$A:$A,0)),"") | J7: =IFERROR(INDEX(Prices!$E:$E,MATCH("Equity|"&C7&"|"&B7,Prices!$A:$A,0)),0) | K7: =IF(D7="THB",1,FXRate) | L7: =IFERROR(H7*I7*K7,0) | M7: =IFERROR(H7*J7*K7,0) | N7: =M7-L7 | O7: =IFERROR(N7/L7,0)
A8: 4 | E8: =IFERROR(INDEX(Reference!$E:$E,MATCH("Equity|"&C8&"|"&B8,Reference!$A:$A,0)),"") | F8: =IFERROR(INDEX(Reference!$G:$G,MATCH("Equity|"&C8&"|"&B8,Reference!$A:$A,0)),"") | G8: =IFERROR(INDEX(Reference!$H:$H,MATCH("Equity|"&C8&"|"&B8,Reference!$A:$A,0)),"") | J8: =IFERROR(INDEX(Prices!$E:$E,MATCH("Equity|"&C8&"|"&B8,Prices!$A:$A,0)),0) | K8: =IF(D8="THB",1,FXRate) | L8: =IFERROR(H8*I8*K8,0) | M8: =IFERROR(H8*J8*K8,0) | N8: =M8-L8 | O8: =IFERROR(N8/L8,0)
A9: 5 | E9: =IFERROR(INDEX(Reference!$E:$E,MATCH("Equity|"&C9&"|"&B9,Reference!$A:$A,0)),"") | F9: =IFERROR(INDEX(Reference!$G:$G,MATCH("Equity|"&C9&"|"&B9,Reference!$A:$A,0)),"") | G9: =IFERROR(INDEX(Reference!$H:$H,MATCH("Equity|"&C9&"|"&B9,Reference!$A:$A,0)),"") | J9: =IFERROR(INDEX(Prices!$E:$E,MATCH("Equity|"&C9&"|"&B9,Prices!$A:$A,0)),0) | K9: =IF(D9="THB",1,FXRate) | L9: =IFERROR(H9*I9*K9,0) | M9: =IFERROR(H9*J9*K9,0) | N9: =M9-L9 | O9: =IFERROR(N9/L9,0)
A10: 6 | E10: =IFERROR(INDEX(Reference!$E:$E,MATCH("Equity|"&C10&"|"&B10,Reference!$A:$A,0)),"") | F10: =IFERROR(INDEX(Reference!$G:$G,MATCH("Equity|"&C10&"|"&B10,Reference!$A:$A,0)),"") | G10: =IFERROR(INDEX(Reference!$H:$H,MATCH("Equity|"&C10&"|"&B10,Reference!$A:$A,0)),"") | J10: =IFERROR(INDEX(Prices!$E:$E,MATCH("Equity|"&C10&"|"&B10,Prices!$A:$A,0)),0) | K10: =IF(D10="THB",1,FXRate) | L10: =IFERROR(H10*I10*K10,0) | M10: =IFERROR(H10*J10*K10,0) | N10: =M10-L10 | O10: =IFERROR(N10/L10,0)
A11: 7 | E11: =IFERROR(INDEX(Reference!$E:$E,MATCH("Equity|"&C11&"|"&B11,Reference!$A:$A,0)),"") | F11: =IFERROR(INDEX(Reference!$G:$G,MATCH("Equity|"&C11&"|"&B11,Reference!$A:$A,0)),"") | G11: =IFERROR(INDEX(Reference!$H:$H,MATCH("Equity|"&C11&"|"&B11,Reference!$A:$A,0)),"") | J11: =IFERROR(INDEX(Prices!$E:$E,MATCH("Equity|"&C11&"|"&B11,Prices!$A:$A,0)),0) | K11: =IF(D11="THB",1,FXRate) | L11: =IFERROR(H11*I11*K11,0) | M11: =IFERROR(H11*J11*K11,0) | N11: =M11-L11 | O11: =IFERROR(N11/L11,0)
A12: 8 | E12: =IFERROR(INDEX(Reference!$E:$E,MATCH("Equity|"&C12&"|"&B12,Reference!$A:$A,0)),"") | F12: =IFERROR(INDEX(Reference!$G:$G,MATCH("Equity|"&C12&"|"&B12,Reference!$A:$A,0)),"") | G12: =IFERROR(INDEX(Reference!$H:$H,MATCH("Equity|"&C12&"|"&B12,Reference!$A:$A,0)),"") | J12: =IFERROR(INDEX(Prices!$E:$E,MATCH("Equity|"&C12&"|"&B12,Prices!$A:$A,0)),0) | K12: =IF(D12="THB",1,FXRate) | L12: =IFERROR(H12*I12*K12,0) | M12: =IFERROR(H12*J12*K12,0) | N12: =M12-L12 | O12: =IFERROR(N12/L12,0)
A13: 9 | E13: =IFERROR(INDEX(Reference!$E:$E,MATCH("Equity|"&C13&"|"&B13,Reference!$A:$A,0)),"") | F13: =IFERROR(INDEX(Reference!$G:$G,MATCH("Equity|"&C13&"|"&B13,Reference!$A:$A,0)),"") | G13: =IFERROR(INDEX(Reference!$H:$H,MATCH("Equity|"&C13&"|"&B13,Reference!$A:$A,0)),"") | J13: =IFERROR(INDEX(Prices!$E:$E,MATCH("Equity|"&C13&"|"&B13,Prices!$A:$A,0)),0) | K13: =IF(D13="THB",1,FXRate) | L13: =IFERROR(H13*I13*K13,0) | M13: =IFERROR(H13*J13*K13,0) | N13: =M13-L13 | O13: =IFERROR(N13/L13,0)
A14: 10 | E14: =IFERROR(INDEX(Reference!$E:$E,MATCH("Equity|"&C14&"|"&B14,Reference!$A:$A,0)),"") | F14: =IFERROR(INDEX(Reference!$G:$G,MATCH("Equity|"&C14&"|"&B14,Reference!$A:$A,0)),"") | G14: =IFERROR(INDEX(Reference!$H:$H,MATCH("Equity|"&C14&"|"&B14,Reference!$A:$A,0)),"") | J14: =IFERROR(INDEX(Prices!$E:$E,MATCH("Equity|"&C14&"|"&B14,Prices!$A:$A,0)),0) | K14: =IF(D14="THB",1,FXRate) | L14: =IFERROR(H14*I14*K14,0) | M14: =IFERROR(H14*J14*K14,0) | N14: =M14-L14 | O14: =IFERROR(N14/L14,0)
A15: 11 | E15: =IFERROR(INDEX(Reference!$E:$E,MATCH("Equity|"&C15&"|"&B15,Reference!$A:$A,0)),"") | F15: =IFERROR(INDEX(Reference!$G:$G,MATCH("Equity|"&C15&"|"&B15,Reference!$A:$A,0)),"") | G15: =IFERROR(INDEX(Reference!$H:$H,MATCH("Equity|"&C15&"|"&B15,Reference!$A:$A,0)),"") | J15: =IFERROR(INDEX(Prices!$E:$E,MATCH("Equity|"&C15&"|"&B15,Prices!$A:$A,0)),0) | K15: =IF(D15="THB",1,FXRate) | L15: =IFERROR(H15*I15*K15,0) | M15: =IFERROR(H15*J15*K15,0) | N15: =M15-L15 | O15: =IFERROR(N15/L15,0)
A16: 12 | E16: =IFERROR(INDEX(Reference!$E:$E,MATCH("Equity|"&C16&"|"&B16,Reference!$A:$A,0)),"") | F16: =IFERROR(INDEX(Reference!$G:$G,MATCH("Equity|"&C16&"|"&B16,Reference!$A:$A,0)),"") | G16: =IFERROR(INDEX(Reference!$H:$H,MATCH("Equity|"&C16&"|"&B16,Reference!$A:$A,0)),"") | J16: =IFERROR(INDEX(Prices!$E:$E,MATCH("Equity|"&C16&"|"&B16,Prices!$A:$A,0)),0) | K16: =IF(D16="THB",1,FXRate) | L16: =IFERROR(H16*I16*K16,0) | M16: =IFERROR(H16*J16*K16,0) | N16: =M16-L16 | O16: =IFERROR(N16/L16,0)
A17: 13 | E17: =IFERROR(INDEX(Reference!$E:$E,MATCH("Equity|"&C17&"|"&B17,Reference!$A:$A,0)),"") | F17: =IFERROR(INDEX(Reference!$G:$G,MATCH("Equity|"&C17&"|"&B17,Reference!$A:$A,0)),"") | G17: =IFERROR(INDEX(Reference!$H:$H,MATCH("Equity|"&C17&"|"&B17,Reference!$A:$A,0)),"") | J17: =IFERROR(INDEX(Prices!$E:$E,MATCH("Equity|"&C17&"|"&B17,Prices!$A:$A,0)),0) | K17: =IF(D17="THB",1,FXRate) | L17: =IFERROR(H17*I17*K17,0) | M17: =IFERROR(H17*J17*K17,0) | N17: =M17-L17 | O17: =IFERROR(N17/L17,0)
A18: 14 | E18: =IFERROR(INDEX(Reference!$E:$E,MATCH("Equity|"&C18&"|"&B18,Reference!$A:$A,0)),"") | F18: =IFERROR(INDEX(Reference!$G:$G,MATCH("Equity|"&C18&"|"&B18,Reference!$A:$A,0)),"") | G18: =IFERROR(INDEX(Reference!$H:$H,MATCH("Equity|"&C18&"|"&B18,Reference!$A:$A,0)),"") | K18: =IF(D18="THB",1,FXRate) | L18: =191552.09*K18 | M18: =191552.09*K18 | N18: =M18-L18 | O18: =IFERROR(N18/L18,0)
A19: 15 | E19: =IFERROR(INDEX(Reference!$E:$E,MATCH("Equity|"&C19&"|"&B19,Reference!$A:$A,0)),"") | F19: =IFERROR(INDEX(Reference!$G:$G,MATCH("Equity|"&C19&"|"&B19,Reference!$A:$A,0)),"") | G19: =IFERROR(INDEX(Reference!$H:$H,MATCH("Equity|"&C19&"|"&B19,Reference!$A:$A,0)),"") | J19: =IFERROR(INDEX(Prices!$E:$E,MATCH("Equity|"&C19&"|"&B19,Prices!$A:$A,0)),0) | K19: =IF(D19="THB",1,FXRate) | L19: =IFERROR(H19*I19*K19,0) | M19: =IFERROR(H19*J19*K19,0) | N19: =M19-L19 | O19: =IFERROR(N19/L19,0)
A20: 16 | E20: =IFERROR(INDEX(Reference!$E:$E,MATCH("Equity|"&C20&"|"&B20,Reference!$A:$A,0)),"") | F20: =IFERROR(INDEX(Reference!$G:$G,MATCH("Equity|"&C20&"|"&B20,Reference!$A:$A,0)),"") | G20: =IFERROR(INDEX(Reference!$H:$H,MATCH("Equity|"&C20&"|"&B20,Reference!$A:$A,0)),"") | J20: =IFERROR(INDEX(Prices!$E:$E,MATCH("Equity|"&C20&"|"&B20,Prices!$A:$A,0)),0) | K20: =IF(D20="THB",1,FXRate) | L20: =IFERROR(H20*I20*K20,0) | M20: =IFERROR(H20*J20*K20,0) | N20: =M20-L20 | O20: =IFERROR(N20/L20,0)
A21: 17 | E21: =IFERROR(INDEX(Reference!$E:$E,MATCH("Equity|"&C21&"|"&B21,Reference!$A:$A,0)),"") | F21: =IFERROR(INDEX(Reference!$G:$G,MATCH("Equity|"&C21&"|"&B21,Reference!$A:$A,0)),"") | G21: =IFERROR(INDEX(Reference!$H:$H,MATCH("Equity|"&C21&"|"&B21,Reference!$A:$A,0)),"") | J21: =IFERROR(INDEX(Prices!$E:$E,MATCH("Equity|"&C21&"|"&B21,Prices!$A:$A,0)),0) | K21: =IF(D21="THB",1,FXRate) | L21: =IFERROR(H21*I21*K21,0) | M21: =IFERROR(H21*J21*K21,0) | N21: =M21-L21 | O21: =IFERROR(N21/L21,0)
A22: 18 | E22: =IFERROR(INDEX(Reference!$E:$E,MATCH("Equity|"&C22&"|"&B22,Reference!$A:$A,0)),"") | F22: =IFERROR(INDEX(Reference!$G:$G,MATCH("Equity|"&C22&"|"&B22,Reference!$A:$A,0)),"") | G22: =IFERROR(INDEX(Reference!$H:$H,MATCH("Equity|"&C22&"|"&B22,Reference!$A:$A,0)),"") | J22: =IFERROR(INDEX(Prices!$E:$E,MATCH("Equity|"&C22&"|"&B22,Prices!$A:$A,0)),0) | K22: =IF(D22="THB",1,FXRate) | L22: =IFERROR(H22*I22*K22,0) | M22: =IFERROR(H22*J22*K22,0) | N22: =M22-L22 | O22: =IFERROR(N22/L22,0)
A23: 19 | E23: =IFERROR(INDEX(Reference!$E:$E,MATCH("Equity|"&C23&"|"&B23,Reference!$A:$A,0)),"") | F23: =IFERROR(INDEX(Reference!$G:$G,MATCH("Equity|"&C23&"|"&B23,Reference!$A:$A,0)),"") | G23: =IFERROR(INDEX(Reference!$H:$H,MATCH("Equity|"&C23&"|"&B23,Reference!$A:$A,0)),"") | K23: =IF(D23="THB",1,FXRate) | L23: =92974.83*K23 | M23: =92974.83*K23 | N23: =M23-L23 | O23: =IFERROR(N23/L23,0)
A24: 20 | E24: =IFERROR(INDEX(Reference!$E:$E,MATCH("Equity|"&C24&"|"&B24,Reference!$A:$A,0)),"") | F24: =IFERROR(INDEX(Reference!$G:$G,MATCH("Equity|"&C24&"|"&B24,Reference!$A:$A,0)),"") | G24: =IFERROR(INDEX(Reference!$H:$H,MATCH("Equity|"&C24&"|"&B24,Reference!$A:$A,0)),"") | K24: =IF(D24="THB",1,FXRate) | L24: =22415.74*K24 | M24: =22415.74*K24 | N24: =M24-L24 | O24: =IFERROR(N24/L24,0)
A25: 21 | E25: =IFERROR(INDEX(Reference!$E:$E,MATCH("Equity|"&C25&"|"&B25,Reference!$A:$A,0)),"") | F25: =IFERROR(INDEX(Reference!$G:$G,MATCH("Equity|"&C25&"|"&B25,Reference!$A:$A,0)),"") | G25: =IFERROR(INDEX(Reference!$H:$H,MATCH("Equity|"&C25&"|"&B25,Reference!$A:$A,0)),"") | J25: =IFERROR(INDEX(Prices!$E:$E,MATCH("Equity|"&C25&"|"&B25,Prices!$A:$A,0)),0) | K25: =IF(D25="THB",1,FXRate) | L25: =IFERROR(H25*I25*K25,0) | M25: =IFERROR(H25*J25*K25,0) | N25: =M25-L25 | O25: =IFERROR(N25/L25,0)
A26: 22 | E26: =IFERROR(INDEX(Reference!$E:$E,MATCH("Equity|"&C26&"|"&B26,Reference!$A:$A,0)),"") | F26: =IFERROR(INDEX(Reference!$G:$G,MATCH("Equity|"&C26&"|"&B26,Reference!$A:$A,0)),"") | G26: =IFERROR(INDEX(Reference!$H:$H,MATCH("Equity|"&C26&"|"&B26,Reference!$A:$A,0)),"") | J26: =IFERROR(INDEX(Prices!$E:$E,MATCH("Equity|"&C26&"|"&B26,Prices!$A:$A,0)),0) | K26: =IF(D26="THB",1,FXRate) | L26: =IFERROR(H26*I26*K26,0) | M26: =IFERROR(H26*J26*K26,0) | N26: =M26-L26 | O26: =IFERROR(N26/L26,0)
A27: 23 | E27: =IFERROR(INDEX(Reference!$E:$E,MATCH("Equity|"&C27&"|"&B27,Reference!$A:$A,0)),"") | F27: =IFERROR(INDEX(Reference!$G:$G,MATCH("Equity|"&C27&"|"&B27,Reference!$A:$A,0)),"") | G27: =IFERROR(INDEX(Reference!$H:$H,MATCH("Equity|"&C27&"|"&B27,Reference!$A:$A,0)),"") | J27: =IFERROR(INDEX(Prices!$E:$E,MATCH("Equity|"&C27&"|"&B27,Prices!$A:$A,0)),0) | K27: =IF(D27="THB",1,FXRate) | L27: =IFERROR(H27*I27*K27,0) | M27: =IFERROR(H27*J27*K27,0) | N27: =M27-L27 | O27: =IFERROR(N27/L27,0)
A28: 24 | E28: =IFERROR(INDEX(Reference!$E:$E,MATCH("Equity|"&C28&"|"&B28,Reference!$A:$A,0)),"") | F28: =IFERROR(INDEX(Reference!$G:$G,MATCH("Equity|"&C28&"|"&B28,Reference!$A:$A,0)),"") | G28: =IFERROR(INDEX(Reference!$H:$H,MATCH("Equity|"&C28&"|"&B28,Reference!$A:$A,0)),"") | J28: =IFERROR(INDEX(Prices!$E:$E,MATCH("Equity|"&C28&"|"&B28,Prices!$A:$A,0)),0) | K28: =IF(D28="THB",1,FXRate) | L28: =IFERROR(H28*I28*K28,0) | M28: =IFERROR(H28*J28*K28,0) | N28: =M28-L28 | O28: =IFERROR(N28/L28,0)
A29: 25 | E29: =IFERROR(INDEX(Reference!$E:$E,MATCH("Equity|"&C29&"|"&B29,Reference!$A:$A,0)),"") | F29: =IFERROR(INDEX(Reference!$G:$G,MATCH("Equity|"&C29&"|"&B29,Reference!$A:$A,0)),"") | G29: =IFERROR(INDEX(Reference!$H:$H,MATCH("Equity|"&C29&"|"&B29,Reference!$A:$A,0)),"") | J29: =IFERROR(INDEX(Prices!$E:$E,MATCH("Equity|"&C29&"|"&B29,Prices!$A:$A,0)),0) | K29: =IF(D29="THB",1,FXRate) | L29: =IFERROR(H29*I29*K29,0) | M29: =IFERROR(H29*J29*K29,0) | N29: =M29-L29 | O29: =IFERROR(N29/L29,0)
A30: 26 | E30: =IFERROR(INDEX(Reference!$E:$E,MATCH("Equity|"&C30&"|"&B30,Reference!$A:$A,0)),"") | F30: =IFERROR(INDEX(Reference!$G:$G,MATCH("Equity|"&C30&"|"&B30,Reference!$A:$A,0)),"") | G30: =IFERROR(INDEX(Reference!$H:$H,MATCH("Equity|"&C30&"|"&B30,Reference!$A:$A,0)),"") | J30: =IFERROR(INDEX(Prices!$E:$E,MATCH("Equity|"&C30&"|"&B30,Prices!$A:$A,0)),0) | K30: =IF(D30="THB",1,FXRate) | L30: =IFERROR(H30*I30*K30,0) | M30: =IFERROR(H30*J30*K30,0) | N30: =M30-L30 | O30: =IFERROR(N30/L30,0)
A31: 27 | E31: =IFERROR(INDEX(Reference!$E:$E,MATCH("Equity|"&C31&"|"&B31,Reference!$A:$A,0)),"") | F31: =IFERROR(INDEX(Reference!$G:$G,MATCH("Equity|"&C31&"|"&B31,Reference!$A:$A,0)),"") | G31: =IFERROR(INDEX(Reference!$H:$H,MATCH("Equity|"&C31&"|"&B31,Reference!$A:$A,0)),"") | J31: =IFERROR(INDEX(Prices!$E:$E,MATCH("Equity|"&C31&"|"&B31,Prices!$A:$A,0)),0) | K31: =IF(D31="THB",1,FXRate) | L31: =IFERROR(H31*I31*K31,0) | M31: =IFERROR(H31*J31*K31,0) | N31: =M31-L31 | O31: =IFERROR(N31/L31,0)
A32: 28 | E32: =IFERROR(INDEX(Reference!$E:$E,MATCH("Equity|"&C32&"|"&B32,Reference!$A:$A,0)),"") | F32: =IFERROR(INDEX(Reference!$G:$G,MATCH("Equity|"&C32&"|"&B32,Reference!$A:$A,0)),"") | G32: =IFERROR(INDEX(Reference!$H:$H,MATCH("Equity|"&C32&"|"&B32,Reference!$A:$A,0)),"") | J32: =IFERROR(INDEX(Prices!$E:$E,MATCH("Equity|"&C32&"|"&B32,Prices!$A:$A,0)),0) | K32: =IF(D32="THB",1,FXRate) | L32: =IFERROR(H32*I32*K32,0) | M32: =IFERROR(H32*J32*K32,0) | N32: =M32-L32 | O32: =IFERROR(N32/L32,0)
A33: 29 | E33: =IFERROR(INDEX(Reference!$E:$E,MATCH("Equity|"&C33&"|"&B33,Reference!$A:$A,0)),"") | F33: =IFERROR(INDEX(Reference!$G:$G,MATCH("Equity|"&C33&"|"&B33,Reference!$A:$A,0)),"") | G33: =IFERROR(INDEX(Reference!$H:$H,MATCH("Equity|"&C33&"|"&B33,Reference!$A:$A,0)),"") | J33: =IFERROR(INDEX(Prices!$E:$E,MATCH("Equity|"&C33&"|"&B33,Prices!$A:$A,0)),0) | K33: =IF(D33="THB",1,FXRate) | L33: =IFERROR(H33*I33*K33,0) | M33: =IFERROR(H33*J33*K33,0) | N33: =M33-L33 | O33: =IFERROR(N33/L33,0)
A34: 30 | E34: =IFERROR(INDEX(Reference!$E:$E,MATCH("Equity|"&C34&"|"&B34,Reference!$A:$A,0)),"") | F34: =IFERROR(INDEX(Reference!$G:$G,MATCH("Equity|"&C34&"|"&B34,Reference!$A:$A,0)),"") | G34: =IFERROR(INDEX(Reference!$H:$H,MATCH("Equity|"&C34&"|"&B34,Reference!$A:$A,0)),"") | J34: =IFERROR(INDEX(Prices!$E:$E,MATCH("Equity|"&C34&"|"&B34,Prices!$A:$A,0)),0) | K34: =IF(D34="THB",1,FXRate) | L34: =IFERROR(H34*I34*K34,0) | M34: =IFERROR(H34*J34*K34,0) | N34: =M34-L34 | O34: =IFERROR(N34/L34,0)
A35: 31 | E35: =IFERROR(INDEX(Reference!$E:$E,MATCH("Equity|"&C35&"|"&B35,Reference!$A:$A,0)),"") | F35: =IFERROR(INDEX(Reference!$G:$G,MATCH("Equity|"&C35&"|"&B35,Reference!$A:$A,0)),"") | G35: =IFERROR(INDEX(Reference!$H:$H,MATCH("Equity|"&C35&"|"&B35,Reference!$A:$A,0)),"") | J35: =IFERROR(INDEX(Prices!$E:$E,MATCH("Equity|"&C35&"|"&B35,Prices!$A:$A,0)),0) | K35: =IF(D35="THB",1,FXRate) | L35: =IFERROR(H35*I35*K35,0) | M35: =IFERROR(H35*J35*K35,0) | N35: =M35-L35 | O35: =IFERROR(N35/L35,0)
A36: 32 | E36: =IFERROR(INDEX(Reference!$E:$E,MATCH("Equity|"&C36&"|"&B36,Reference!$A:$A,0)),"") | F36: =IFERROR(INDEX(Reference!$G:$G,MATCH("Equity|"&C36&"|"&B36,Reference!$A:$A,0)),"") | G36: =IFERROR(INDEX(Reference!$H:$H,MATCH("Equity|"&C36&"|"&B36,Reference!$A:$A,0)),"") | J36: =IFERROR(INDEX(Prices!$E:$E,MATCH("Equity|"&C36&"|"&B36,Prices!$A:$A,0)),0) | K36: =IF(D36="THB",1,FXRate) | L36: =IFERROR(H36*I36*K36,0) | M36: =IFERROR(H36*J36*K36,0) | N36: =M36-L36 | O36: =IFERROR(N36/L36,0)
... A43: 39 | E43: =IFERROR(INDEX(Reference!$E:$E,MATCH("Equity|"&C43&"|"&B43,Reference!$A:$A,0)),"") | F43: =IFERROR(INDEX(Reference!$G:$G,MATCH("Equity|"&C43&"|"&B43,Reference!$A:$A,0)),"") | G43: =IFERROR(INDEX(Reference!$H:$H,MATCH("Equity|"&C43&"|"&B43,Reference!$A:$A,0)),"") | J43: =IFERROR(INDEX(Prices!$E:$E,MATCH("Equity|"&C43&"|"&B43,Prices!$A:$A,0)),0) | K43: =IF(D43="THB",1,FXRate) | L43: =IFERROR(H43*I43*K43,0) | M43: =IFERROR(H43*J43*K43,0) | N43: =M43-L43 | O43: =IFERROR(N43/L43,0)
A44: 40 | E44: =IFERROR(INDEX(Reference!$E:$E,MATCH("Equity|"&C44&"|"&B44,Reference!$A:$A,0)),"") | F44: =IFERROR(INDEX(Reference!$G:$G,MATCH("Equity|"&C44&"|"&B44,Reference!$A:$A,0)),"") | G44: =IFERROR(INDEX(Reference!$H:$H,MATCH("Equity|"&C44&"|"&B44,Reference!$A:$A,0)),"") | K44: =IF(D44="THB",1,FXRate) | L44: =8281.17*K44 | M44: =8281.17*K44 | N44: =M44-L44 | O44: =IFERROR(N44/L44,0)
A45: 41 | E45: =IFERROR(INDEX(Reference!$E:$E,MATCH("Equity|"&C45&"|"&B45,Reference!$A:$A,0)),"") | F45: =IFERROR(INDEX(Reference!$G:$G,MATCH("Equity|"&C45&"|"&B45,Reference!$A:$A,0)),"") | G45: =IFERROR(INDEX(Reference!$H:$H,MATCH("Equity|"&C45&"|"&B45,Reference!$A:$A,0)),"") | K45: =IF(D45="THB",1,FXRate) | L45: =2584.77*K45 | M45: =2584.77*K45 | N45: =M45-L45 | O45: =IFERROR(N45/L45,0)
A46: TOTAL | L46: =SUM(L5:L45) | M46: =SUM(M5:M45) | N46: =SUM(N5:N45) | O46: =IFERROR(N46/L46,0)

Sheet Equities - by Ticker
A2: EQUITIES — ROLLUP BY TICKER
A4: # | B4: Broker | C4: Ticker | D4: Ccy | E4: Asset Class | F4: Geography | G4: Theme | H4: Lots | I4: Shares | J4: Initial Inv (฿) | K4: Current Value (฿) | L4: Unrealized P&L (฿) | M4: P&L %
A5: 1 | E5: =IFERROR(INDEX(Reference!$E:$E,MATCH("Equity|"&C5&"|"&B5,Reference!$A:$A,0)),"") | F5: =IFERROR(INDEX(Reference!$G:$G,MATCH("Equity|"&C5&"|"&B5,Reference!$A:$A,0)),"") | G5: =IFERROR(INDEX(Reference!$H:$H,MATCH("Equity|"&C5&"|"&B5,Reference!$A:$A,0)),"") | H5: =COUNTIFS('Equities - Lots'!$B:$B,B5,'Equities - Lots'!$C:$C,C5) | I5: =SUMIFS('Equities - Lots'!$H:$H,'Equities - Lots'!$B:$B,B5,'Equities - Lots'!$C:$C,C5) | J5: =SUMIFS('Equities - Lots'!$L:$L,'Equities - Lots'!$B:$B,B5,'Equities - Lots'!$C:$C,C5) | K5: =SUMIFS('Equities - Lots'!$M:$M,'Equities - Lots'!$B:$B,B5,'Equities - Lots'!$C:$C,C5) | L5: =K5-J5 | M5: =IFERROR(L5/J5,0)
A6: 2 | E6: =IFERROR(INDEX(Reference!$E:$E,MATCH("Equity|"&C6&"|"&B6,Reference!$A:$A,0)),"") | F6: =IFERROR(INDEX(Reference!$G:$G,MATCH("Equity|"&C6&"|"&B6,Reference!$A:$A,0)),"") | G6: =IFERROR(INDEX(Reference!$H:$H,MATCH("Equity|"&C6&"|"&B6,Reference!$A:$A,0)),"") | H6: =COUNTIFS('Equities - Lots'!$B:$B,B6,'Equities - Lots'!$C:$C,C6) | I6: =SUMIFS('Equities - Lots'!$H:$H,'Equities - Lots'!$B:$B,B6,'Equities - Lots'!$C:$C,C6) | J6: =SUMIFS('Equities - Lots'!$L:$L,'Equities - Lots'!$B:$B,B6,'Equities - Lots'!$C:$C,C6) | K6: =SUMIFS('Equities - Lots'!$M:$M,'Equities - Lots'!$B:$B,B6,'Equities - Lots'!$C:$C,C6) | L6: =K6-J6 | M6: =IFERROR(L6/J6,0)
A7: 3 | E7: =IFERROR(INDEX(Reference!$E:$E,MATCH("Equity|"&C7&"|"&B7,Reference!$A:$A,0)),"") | F7: =IFERROR(INDEX(Reference!$G:$G,MATCH("Equity|"&C7&"|"&B7,Reference!$A:$A,0)),"") | G7: =IFERROR(INDEX(Reference!$H:$H,MATCH("Equity|"&C7&"|"&B7,Reference!$A:$A,0)),"") | H7: =COUNTIFS('Equities - Lots'!$B:$B,B7,'Equities - Lots'!$C:$C,C7) | I7: =SUMIFS('Equities - Lots'!$H:$H,'Equities - Lots'!$B:$B,B7,'Equities - Lots'!$C:$C,C7) | J7: =SUMIFS('Equities - Lots'!$L:$L,'Equities - Lots'!$B:$B,B7,'Equities - Lots'!$C:$C,C7) | K7: =SUMIFS('Equities - Lots'!$M:$M,'Equities - Lots'!$B:$B,B7,'Equities - Lots'!$C:$C,C7) | L7: =K7-J7 | M7: =IFERROR(L7/J7,0)
A8: 4 | E8: =IFERROR(INDEX(Reference!$E:$E,MATCH("Equity|"&C8&"|"&B8,Reference!$A:$A,0)),"") | F8: =IFERROR(INDEX(Reference!$G:$G,MATCH("Equity|"&C8&"|"&B8,Reference!$A:$A,0)),"") | G8: =IFERROR(INDEX(Reference!$H:$H,MATCH("Equity|"&C8&"|"&B8,Reference!$A:$A,0)),"") | H8: =COUNTIFS('Equities - Lots'!$B:$B,B8,'Equities - Lots'!$C:$C,C8) | I8: =SUMIFS('Equities - Lots'!$H:$H,'Equities - Lots'!$B:$B,B8,'Equities - Lots'!$C:$C,C8) | J8: =SUMIFS('Equities - Lots'!$L:$L,'Equities - Lots'!$B:$B,B8,'Equities - Lots'!$C:$C,C8) | K8: =SUMIFS('Equities - Lots'!$M:$M,'Equities - Lots'!$B:$B,B8,'Equities - Lots'!$C:$C,C8) | L8: =K8-J8 | M8: =IFERROR(L8/J8,0)
A9: 5 | E9: =IFERROR(INDEX(Reference!$E:$E,MATCH("Equity|"&C9&"|"&B9,Reference!$A:$A,0)),"") | F9: =IFERROR(INDEX(Reference!$G:$G,MATCH("Equity|"&C9&"|"&B9,Reference!$A:$A,0)),"") | G9: =IFERROR(INDEX(Reference!$H:$H,MATCH("Equity|"&C9&"|"&B9,Reference!$A:$A,0)),"") | H9: =COUNTIFS('Equities - Lots'!$B:$B,B9,'Equities - Lots'!$C:$C,C9) | I9: =SUMIFS('Equities - Lots'!$H:$H,'Equities - Lots'!$B:$B,B9,'Equities - Lots'!$C:$C,C9) | J9: =SUMIFS('Equities - Lots'!$L:$L,'Equities - Lots'!$B:$B,B9,'Equities - Lots'!$C:$C,C9) | K9: =SUMIFS('Equities - Lots'!$M:$M,'Equities - Lots'!$B:$B,B9,'Equities - Lots'!$C:$C,C9) | L9: =K9-J9 | M9: =IFERROR(L9/J9,0)
A10: 6 | E10: =IFERROR(INDEX(Reference!$E:$E,MATCH("Equity|"&C10&"|"&B10,Reference!$A:$A,0)),"") | F10: =IFERROR(INDEX(Reference!$G:$G,MATCH("Equity|"&C10&"|"&B10,Reference!$A:$A,0)),"") | G10: =IFERROR(INDEX(Reference!$H:$H,MATCH("Equity|"&C10&"|"&B10,Reference!$A:$A,0)),"") | H10: =COUNTIFS('Equities - Lots'!$B:$B,B10,'Equities - Lots'!$C:$C,C10) | I10: =SUMIFS('Equities - Lots'!$H:$H,'Equities - Lots'!$B:$B,B10,'Equities - Lots'!$C:$C,C10) | J10: =SUMIFS('Equities - Lots'!$L:$L,'Equities - Lots'!$B:$B,B10,'Equities - Lots'!$C:$C,C10) | K10: =SUMIFS('Equities - Lots'!$M:$M,'Equities - Lots'!$B:$B,B10,'Equities - Lots'!$C:$C,C10) | L10: =K10-J10 | M10: =IFERROR(L10/J10,0)
A11: 7 | E11: =IFERROR(INDEX(Reference!$E:$E,MATCH("Equity|"&C11&"|"&B11,Reference!$A:$A,0)),"") | F11: =IFERROR(INDEX(Reference!$G:$G,MATCH("Equity|"&C11&"|"&B11,Reference!$A:$A,0)),"") | G11: =IFERROR(INDEX(Reference!$H:$H,MATCH("Equity|"&C11&"|"&B11,Reference!$A:$A,0)),"") | H11: =COUNTIFS('Equities - Lots'!$B:$B,B11,'Equities - Lots'!$C:$C,C11) | I11: =SUMIFS('Equities - Lots'!$H:$H,'Equities - Lots'!$B:$B,B11,'Equities - Lots'!$C:$C,C11) | J11: =SUMIFS('Equities - Lots'!$L:$L,'Equities - Lots'!$B:$B,B11,'Equities - Lots'!$C:$C,C11) | K11: =SUMIFS('Equities - Lots'!$M:$M,'Equities - Lots'!$B:$B,B11,'Equities - Lots'!$C:$C,C11) | L11: =K11-J11 | M11: =IFERROR(L11/J11,0)
A12: 8 | E12: =IFERROR(INDEX(Reference!$E:$E,MATCH("Equity|"&C12&"|"&B12,Reference!$A:$A,0)),"") | F12: =IFERROR(INDEX(Reference!$G:$G,MATCH("Equity|"&C12&"|"&B12,Reference!$A:$A,0)),"") | G12: =IFERROR(INDEX(Reference!$H:$H,MATCH("Equity|"&C12&"|"&B12,Reference!$A:$A,0)),"") | H12: =COUNTIFS('Equities - Lots'!$B:$B,B12,'Equities - Lots'!$C:$C,C12) | I12: =SUMIFS('Equities - Lots'!$H:$H,'Equities - Lots'!$B:$B,B12,'Equities - Lots'!$C:$C,C12) | J12: =SUMIFS('Equities - Lots'!$L:$L,'Equities - Lots'!$B:$B,B12,'Equities - Lots'!$C:$C,C12) | K12: =SUMIFS('Equities - Lots'!$M:$M,'Equities - Lots'!$B:$B,B12,'Equities - Lots'!$C:$C,C12) | L12: =K12-J12 | M12: =IFERROR(L12/J12,0)
A13: 9 | E13: =IFERROR(INDEX(Reference!$E:$E,MATCH("Equity|"&C13&"|"&B13,Reference!$A:$A,0)),"") | F13: =IFERROR(INDEX(Reference!$G:$G,MATCH("Equity|"&C13&"|"&B13,Reference!$A:$A,0)),"") | G13: =IFERROR(INDEX(Reference!$H:$H,MATCH("Equity|"&C13&"|"&B13,Reference!$A:$A,0)),"") | H13: =COUNTIFS('Equities - Lots'!$B:$B,B13,'Equities - Lots'!$C:$C,C13) | I13: =SUMIFS('Equities - Lots'!$H:$H,'Equities - Lots'!$B:$B,B13,'Equities - Lots'!$C:$C,C13) | J13: =SUMIFS('Equities - Lots'!$L:$L,'Equities - Lots'!$B:$B,B13,'Equities - Lots'!$C:$C,C13) | K13: =SUMIFS('Equities - Lots'!$M:$M,'Equities - Lots'!$B:$B,B13,'Equities - Lots'!$C:$C,C13) | L13: =K13-J13 | M13: =IFERROR(L13/J13,0)
A14: 10 | E14: =IFERROR(INDEX(Reference!$E:$E,MATCH("Equity|"&C14&"|"&B14,Reference!$A:$A,0)),"") | F14: =IFERROR(INDEX(Reference!$G:$G,MATCH("Equity|"&C14&"|"&B14,Reference!$A:$A,0)),"") | G14: =IFERROR(INDEX(Reference!$H:$H,MATCH("Equity|"&C14&"|"&B14,Reference!$A:$A,0)),"") | H14: =COUNTIFS('Equities - Lots'!$B:$B,B14,'Equities - Lots'!$C:$C,C14) | I14: =SUMIFS('Equities - Lots'!$H:$H,'Equities - Lots'!$B:$B,B14,'Equities - Lots'!$C:$C,C14) | J14: =SUMIFS('Equities - Lots'!$L:$L,'Equities - Lots'!$B:$B,B14,'Equities - Lots'!$C:$C,C14) | K14: =SUMIFS('Equities - Lots'!$M:$M,'Equities - Lots'!$B:$B,B14,'Equities - Lots'!$C:$C,C14) | L14: =K14-J14 | M14: =IFERROR(L14/J14,0)
